Running Release|Win32 interpreter...
>>>>>>>>>>>>>>>>>> get_exception_group <<<<<<<<<<<<<<<<<<<<
ExceptionGroup({ExceptionGroup({ValueError('bad value: g0'), ValueError('bad value: f0')}), ValueError('bad value: g1'), ValueError('bad value: f1')})
[0]  <frame at 0x01F33A70, file 'C:\\Users\\User\\src\\cpython\\exception_group.py', line 41, code get_exception_group>
[0]  <frame at 0x01DDFC88, file 'C:\\Users\\User\\src\\cpython\\exception_group.py', line 35, code propagator>
[0]  <frame at 0x01D76DA8, file 'C:\\Users\\User\\src\\cpython\\exception_group.py', line 32, code aggregator1>
---------------------------------------
bad value: g0
[0]      <frame at 0x020A41A0, file 'C:\\Users\\User\\src\\cpython\\exception_group.py', line 22, code aggregator>
[0]      <frame at 0x01F60708, file 'C:\\Users\\User\\src\\cpython\\exception_group.py', line 9, code g>
---------------------------------------
bad value: f0
[0]      <frame at 0x020A41A0, file 'C:\\Users\\User\\src\\cpython\\exception_group.py', line 22, code aggregator>
[0]      <frame at 0x01F602E8, file 'C:\\Users\\User\\src\\cpython\\exception_group.py', line 6, code f>
---------------------------------------
bad value: g1
[0]      <frame at 0x01F5AD18, file 'C:\\Users\\User\\src\\cpython\\exception_group.py', line 10, code g1>
[0]      <frame at 0x020A61B0, file 'C:\\Users\\User\\src\\cpython\\exception_group.py', line 9, code g>
---------------------------------------
bad value: f1
[0]      <frame at 0x01F605A8, file 'C:\\Users\\User\\src\\cpython\\exception_group.py', line 7, code f1>
[0]      <frame at 0x01F60868, file 'C:\\Users\\User\\src\\cpython\\exception_group.py', line 6, code f>
