Running Release|Win32 interpreter...
>>>>>>>>>>>>>>>>>> get_exception_group <<<<<<<<<<<<<<<<<<<<
{ExceptionGroup({ValueError('bad value: f0'), ValueError('bad value: g0')}), ValueError('bad value: g1'), ValueError('bad value: f1')}
 <frame at 0x016A3A70, file 'C:\\Users\\User\\src\\cpython\\exception_group.py', line 41, code get_exception_group>
 <frame at 0x0168FC88, file 'C:\\Users\\User\\src\\cpython\\exception_group.py', line 35, code propagator>
 <frame at 0x01146DA8, file 'C:\\Users\\User\\src\\cpython\\exception_group.py', line 32, code aggregator1>
---------------------------------------
bad value: f0
     <frame at 0x017141A0, file 'C:\\Users\\User\\src\\cpython\\exception_group.py', line 22, code aggregator>
     <frame at 0x016D02E8, file 'C:\\Users\\User\\src\\cpython\\exception_group.py', line 6, code f>
---------------------------------------
bad value: g0
     <frame at 0x017141A0, file 'C:\\Users\\User\\src\\cpython\\exception_group.py', line 22, code aggregator>
     <frame at 0x016D0708, file 'C:\\Users\\User\\src\\cpython\\exception_group.py', line 9, code g>
---------------------------------------
bad value: g1
     <frame at 0x016CAD18, file 'C:\\Users\\User\\src\\cpython\\exception_group.py', line 10, code g1>
     <frame at 0x017151B0, file 'C:\\Users\\User\\src\\cpython\\exception_group.py', line 9, code g>
---------------------------------------
bad value: f1
     <frame at 0x016D05A8, file 'C:\\Users\\User\\src\\cpython\\exception_group.py', line 7, code f1>
     <frame at 0x016D0868, file 'C:\\Users\\User\\src\\cpython\\exception_group.py', line 6, code f>
>>>>>>>>>>>>>>>>>> handle_type_errors <<<<<<<<<<<<<<<<<<<<



 ------------- The split-off Type Errors:
[ExceptionGroup(set())]



 ------------- The remaining unhandled:
[ExceptionGroup({ValueError('bad value: f0'), ValueError('bad value: g0')}), ValueError('bad value: f1'), ValueError('bad value: g1')]
---------------------------------------
bad value: g1
     <frame at 0x0114ACF8, file 'C:\\Users\\User\\src\\cpython\\exception_group.py', line 10, code g1>
     <frame at 0x01747D48, file 'C:\\Users\\User\\src\\cpython\\exception_group.py', line 9, code g>
---------------------------------------
bad value: f0
     <frame at 0x016A3D60, file 'C:\\Users\\User\\src\\cpython\\exception_group.py', line 22, code aggregator>
     <frame at 0x01747E98, file 'C:\\Users\\User\\src\\cpython\\exception_group.py', line 6, code f>
---------------------------------------
bad value: g0
     <frame at 0x016A3D60, file 'C:\\Users\\User\\src\\cpython\\exception_group.py', line 22, code aggregator>
     <frame at 0x01756028, file 'C:\\Users\\User\\src\\cpython\\exception_group.py', line 9, code g>
---------------------------------------
bad value: f1
     <frame at 0x0114ABB0, file 'C:\\Users\\User\\src\\cpython\\exception_group.py', line 7, code f1>
     <frame at 0x01747BF8, file 'C:\\Users\\User\\src\\cpython\\exception_group.py', line 6, code f>
>>>>>>>>>>>>>>>>>> handle_value_errors <<<<<<<<<<<<<<<<<<<<



 ------------- The split-off Value Errors:
[ValueError('bad value: f1'), ExceptionGroup({ValueError('bad value: g0'), ValueError('bad value: f0')}), ValueError('bad value: g1')]
---------------------------------------
bad value: g0
     <frame at 0x0174D318, file 'C:\\Users\\User\\src\\cpython\\exception_group.py', line 22, code aggregator>
     <frame at 0x01756568, file 'C:\\Users\\User\\src\\cpython\\exception_group.py', line 9, code g>
---------------------------------------
bad value: f0
     <frame at 0x0174D318, file 'C:\\Users\\User\\src\\cpython\\exception_group.py', line 22, code aggregator>
     <frame at 0x01756418, file 'C:\\Users\\User\\src\\cpython\\exception_group.py', line 6, code f>
---------------------------------------
bad value: f1
     <frame at 0x01758028, file 'C:\\Users\\User\\src\\cpython\\exception_group.py', line 7, code f1>
     <frame at 0x01756178, file 'C:\\Users\\User\\src\\cpython\\exception_group.py', line 6, code f>
---------------------------------------
bad value: g1
     <frame at 0x01758170, file 'C:\\Users\\User\\src\\cpython\\exception_group.py', line 10, code g1>
     <frame at 0x017562C8, file 'C:\\Users\\User\\src\\cpython\\exception_group.py', line 9, code g>



 ------------- The remaining unhandled:
[ExceptionGroup(set())]
