Running Release|Win32 interpreter...


>>>>>>>>>>>>>>>>>> get_exception_group <<<<<<<<<<<<<<<<<<<<
{ValueError('bad value: g1'), TypeError('bad type: h1'), ValueError('bad value: f1'), ExceptionGroup({ValueError('bad value: f0'), ValueError('bad value: g0'), TypeError('bad type: h0')})}
 <frame at 0x015DA758, file 'C:\\Users\\User\\src\\cpython\\exception_group_test.py', line 41, code get_exception_group>
 <frame at 0x015E0868, file 'C:\\Users\\User\\src\\cpython\\exception_group_test.py', line 35, code propagator>
 <frame at 0x01536DA8, file 'C:\\Users\\User\\src\\cpython\\exception_group_test.py', line 32, code aggregator1>
---------------------------------------
bad value: g1
     <frame at 0x015E02E8, file 'C:\\Users\\User\\src\\cpython\\exception_group_test.py', line 10, code g1>
     <frame at 0x015E0708, file 'C:\\Users\\User\\src\\cpython\\exception_group_test.py', line 9, code g>
---------------------------------------
bad type: h1
     <frame at 0x0153AA68, file 'C:\\Users\\User\\src\\cpython\\exception_group_test.py', line 13, code h1>
     <frame at 0x020D4AA8, file 'C:\\Users\\User\\src\\cpython\\exception_group_test.py', line 12, code h>
---------------------------------------
bad value: f1
     <frame at 0x016261B0, file 'C:\\Users\\User\\src\\cpython\\exception_group_test.py', line 7, code f1>
     <frame at 0x016241A0, file 'C:\\Users\\User\\src\\cpython\\exception_group_test.py', line 6, code f>
---------------------------------------
bad value: f0
     <frame at 0x0154DBE8, file 'C:\\Users\\User\\src\\cpython\\exception_group_test.py', line 22, code aggregator>
     <frame at 0x020D4BF8, file 'C:\\Users\\User\\src\\cpython\\exception_group_test.py', line 6, code f>
---------------------------------------
bad value: g0
     <frame at 0x0154DBE8, file 'C:\\Users\\User\\src\\cpython\\exception_group_test.py', line 22, code aggregator>
     <frame at 0x020D4D48, file 'C:\\Users\\User\\src\\cpython\\exception_group_test.py', line 9, code g>
---------------------------------------
bad type: h0
     <frame at 0x0154DBE8, file 'C:\\Users\\User\\src\\cpython\\exception_group_test.py', line 22, code aggregator>
     <frame at 0x020D4E98, file 'C:\\Users\\User\\src\\cpython\\exception_group_test.py', line 12, code h>


>>>>>>>>>>>>>>>>>> handle_type_errors <<<<<<<<<<<<<<<<<<<<

 ------------- The split-off Type Errors:
[TypeError('bad type: h1'), ExceptionGroup({TypeError('bad type: h0')})]
 <frame at 0x015B3A70, file 'C:\\Users\\User\\src\\cpython\\exception_group_test.py', line 48, code handle_type_errors>
 <frame at 0x0153ABB0, file 'C:\\Users\\User\\src\\cpython\\exception_group_test.py', line 35, code propagator>
 <frame at 0x020E6028, file 'C:\\Users\\User\\src\\cpython\\exception_group_test.py', line 32, code aggregator1>
---------------------------------------
bad type: h1
     <frame at 0x020E7028, file 'C:\\Users\\User\\src\\cpython\\exception_group_test.py', line 13, code h1>
     <frame at 0x020E5418, file 'C:\\Users\\User\\src\\cpython\\exception_group_test.py', line 12, code h>
---------------------------------------
bad type: h0
     <frame at 0x015B3D60, file 'C:\\Users\\User\\src\\cpython\\exception_group_test.py', line 22, code aggregator>
     <frame at 0x020E5808, file 'C:\\Users\\User\\src\\cpython\\exception_group_test.py', line 12, code h>



 ------------- The remaining unhandled:
[ValueError('bad value: g1'), ExceptionGroup({ValueError('bad value: g0'), ValueError('bad value: f0')}), ValueError('bad value: f1')]
 <frame at 0x015B3A70, file 'C:\\Users\\User\\src\\cpython\\exception_group_test.py', line 48, code handle_type_errors>
 <frame at 0x0153ABB0, file 'C:\\Users\\User\\src\\cpython\\exception_group_test.py', line 35, code propagator>
 <frame at 0x020E6028, file 'C:\\Users\\User\\src\\cpython\\exception_group_test.py', line 32, code aggregator1>
---------------------------------------
bad value: g1
     <frame at 0x0153AE40, file 'C:\\Users\\User\\src\\cpython\\exception_group_test.py', line 10, code g1>
     <frame at 0x020E52C8, file 'C:\\Users\\User\\src\\cpython\\exception_group_test.py', line 9, code g>
---------------------------------------
bad value: g0
     <frame at 0x015B3D60, file 'C:\\Users\\User\\src\\cpython\\exception_group_test.py', line 22, code aggregator>
     <frame at 0x020E56B8, file 'C:\\Users\\User\\src\\cpython\\exception_group_test.py', line 9, code g>
---------------------------------------
bad value: f0
     <frame at 0x015B3D60, file 'C:\\Users\\User\\src\\cpython\\exception_group_test.py', line 22, code aggregator>
     <frame at 0x020E5568, file 'C:\\Users\\User\\src\\cpython\\exception_group_test.py', line 6, code f>
---------------------------------------
bad value: f1
     <frame at 0x0153ACF8, file 'C:\\Users\\User\\src\\cpython\\exception_group_test.py', line 7, code f1>
     <frame at 0x020E5178, file 'C:\\Users\\User\\src\\cpython\\exception_group_test.py', line 6, code f>


>>>>>>>>>>>>>>>>>> handle_value_errors <<<<<<<<<<<<<<<<<<<<

 ------------- The split-off Value Errors:
[ValueError('bad value: g1'), ValueError('bad value: f1'), ExceptionGroup({ValueError('bad value: g0'), ValueError('bad value: f0')})]
 <frame at 0x020DC1A0, file 'C:\\Users\\User\\src\\cpython\\exception_group_test.py', line 55, code handle_value_errors>
 <frame at 0x020E7170, file 'C:\\Users\\User\\src\\cpython\\exception_group_test.py', line 35, code propagator>
 <frame at 0x020E61A8, file 'C:\\Users\\User\\src\\cpython\\exception_group_test.py', line 32, code aggregator1>
---------------------------------------
bad value: g1
     <frame at 0x020E7400, file 'C:\\Users\\User\\src\\cpython\\exception_group_test.py', line 10, code g1>
     <frame at 0x020E5AA8, file 'C:\\Users\\User\\src\\cpython\\exception_group_test.py', line 9, code g>
---------------------------------------
bad value: f1
     <frame at 0x020E72B8, file 'C:\\Users\\User\\src\\cpython\\exception_group_test.py', line 7, code f1>
     <frame at 0x020E5958, file 'C:\\Users\\User\\src\\cpython\\exception_group_test.py', line 6, code f>
---------------------------------------
bad value: g0
     <frame at 0x020DC318, file 'C:\\Users\\User\\src\\cpython\\exception_group_test.py', line 22, code aggregator>
     <frame at 0x020E5E98, file 'C:\\Users\\User\\src\\cpython\\exception_group_test.py', line 9, code g>
---------------------------------------
bad value: f0
     <frame at 0x020DC318, file 'C:\\Users\\User\\src\\cpython\\exception_group_test.py', line 22, code aggregator>
     <frame at 0x020E5D48, file 'C:\\Users\\User\\src\\cpython\\exception_group_test.py', line 6, code f>

 ------------- The remaining unhandled:
[TypeError('bad type: h1'), ExceptionGroup({TypeError('bad type: h0')})]
 <frame at 0x020DC1A0, file 'C:\\Users\\User\\src\\cpython\\exception_group_test.py', line 55, code handle_value_errors>
 <frame at 0x020E7170, file 'C:\\Users\\User\\src\\cpython\\exception_group_test.py', line 35, code propagator>
 <frame at 0x020E61A8, file 'C:\\Users\\User\\src\\cpython\\exception_group_test.py', line 32, code aggregator1>
---------------------------------------
bad type: h0
     <frame at 0x020DC318, file 'C:\\Users\\User\\src\\cpython\\exception_group_test.py', line 22, code aggregator>
     <frame at 0x020EA028, file 'C:\\Users\\User\\src\\cpython\\exception_group_test.py', line 12, code h>
---------------------------------------
bad type: h1
     <frame at 0x020E7548, file 'C:\\Users\\User\\src\\cpython\\exception_group_test.py', line 13, code h1>
     <frame at 0x020E5BF8, file 'C:\\Users\\User\\src\\cpython\\exception_group_test.py', line 12, code h>
